Workbook

Sheet Summary
A1: HO 42 extraction log - summary
A3: Count by event type
A4: Event type | B4: Rows
A5: Request for troops | B5: =COUNTIF(Events!$C$2:$C$1000,A5) -> 43
A6: Corps founded | B6: =COUNTIF(Events!$C$2:$C$1000,A6) -> 8
A7: Corps armed/expanded | B7: =COUNTIF(Events!$C$2:$C$1000,A7) -> 7
A8: Barracks | B8: =COUNTIF(Events!$C$2:$C$1000,A8) -> 9
A9: Corps forming (context) | B9: =COUNTIF(Events!$C$2:$C$1000,A9) -> 1
A10: Other | B10: =COUNTIF(Events!$C$2:$C$1000,A10) -> 4
A11: TOTAL | B11: =SUM(B5:B10) -> 72
A13: Requests for troops by kind
A14: Request kind | B14: Rows
A15: Actual | B15: =COUNTIFS(Events!$C$2:$C$1000,"Request for troops",Events!$Y$2:$Y$1000,A15) -> 17
A16: Pre-emptive | B16: =COUNTIFS(Events!$C$2:$C$1000,"Request for troops",Events!$Y$2:$Y$1000,A16) -> 17
A17: Contingent | B17: =COUNTIFS(Events!$C$2:$C$1000,"Request for troops",Events!$Y$2:$Y$1000,A17) -> 4
A18: Report only | B18: =COUNTIFS(Events!$C$2:$C$1000,"Request for troops",Events!$Y$2:$Y$1000,A18) -> 5
A19: TOTAL | B19: =SUM(B15:B18) -> 43
A21: By year
A22: Year | B22: Rows
A23: 1789 | B23: =COUNTIF(Events!$P$2:$P$1000,A23) -> 0
A24: 1790 | B24: =COUNTIF(Events!$P$2:$P$1000,A24) -> 2
A25: 1791 | B25: =COUNTIF(Events!$P$2:$P$1000,A25) -> 10
A26: 1792 | B26: =COUNTIF(Events!$P$2:$P$1000,A26) -> 24
A27: 1793 | B27: =COUNTIF(Events!$P$2:$P$1000,A27) -> 2
A28: 1794 | B28: =COUNTIF(Events!$P$2:$P$1000,A28) -> 11
A29: 1795 | B29: =COUNTIF(Events!$P$2:$P$1000,A29) -> 23
A30: 1796 | B30: =COUNTIF(Events!$P$2:$P$1000,A30) -> 0
A31: 1797 | B31: =COUNTIF(Events!$P$2:$P$1000,A31) -> 0
A32: 1798 | B32: =COUNTIF(Events!$P$2:$P$1000,A32) -> 0
A33: 1799 | B33: =COUNTIF(Events!$P$2:$P$1000,A33) -> 0
A34: 1800 | B34: =COUNTIF(Events!$P$2:$P$1000,A34) -> 0
A35: 1801 | B35: =COUNTIF(Events!$P$2:$P$1000,A35) -> 0
A36: TOTAL | B36: =SUM(B23:B35) -> 72
A38: Distinct episodes (all rows) | B38: =SUMPRODUCT((Events!$B$2:$B$1000<>"")/COUNTIF(Events!$B$2:$B$1000,Events!$B$2:$B$1000&"")) -> 61
A39: Rows still to check (Folio basis = Unclear) | B39: =COUNTIF(Events!$I$2:$I$1000,"Unclear - check") -> 18

Sheet Events
A1: Row ID | B1: Episode ID | C1: Event type | D1: Key quote? | E1: Call number | F1: File | G1: PDF page no. | H1: Folio | I1: Folio basis | J1: Link to PDF/Photos | K1: Image status | L1: Transcription status | M1: Transcribed text (key quote) | N1: Date (as written) | O1: Date (ISO) | P1: Year | Q1: Location (as written) | R1: Place (normalised) | S1: County | T1: Writer | U1: Writer role | V1: Addressed to | W1: Home Secretary in office | X1: Disturbance type | Y1: Request kind | Z1: Civil power inadequate? | AA1: Force requested (type & size) | AB1: Military already nearby? | AC1: Response text (if given) | AD1: Outcome | AE1: Response date | AF1: Response location | AG1: Response writer | AH1: Response source | AI1: Notes / flag
A2: HO42-0001 | B2: E01 | C2: Request for troops | D2: N | E2: HO 42/16 | F2: HO-42-16_01.pdf | H2: ff.58, 60, 61 | I2: Unclear - check | K2: Digitised (TNA PDF) | L2: Key quote only | M2: "...should arise any Necessity for the Interference of the Military, it would be expedient for me to know the nearest Place to this Spot where Troops are now station'd... from the War Office, with the Name of the commanding Officer." | N2: 17 Mar 1790 | O2: 1790-03-17 | P2: =IF(O2="","",VALUE(LEFT(O2,4))) -> 1790 | Q2: Keynsham (nr Bristol) | R2: Keynsham | S2: Somerset | T2: Thomas Ireland, magistrate | U2: Magistrate / JP | W2: =IF(O2="","",INDEX(Lookups!$B$2:$B$20,MATCH(O2,Lookups!$A$2:$A$20,1))) -> Grenville | X2: Anti-machinery | Y2: Contingent | Z2: N | AA2: None yet - asks location of nearest troops + CO name | AB2: Unclear | AD2: Not needed | AI2: Anti-machinery/colliers riot vs newly introduced woollen manufactory machines; contingent request for nearest garrison; Ireland preferred civil power. | Outcome (orig.): Not called (dispersed by Riot Act)
A3: HO42-0002 | B3: E02 | C3: Request for troops | D3: N | E3: HO 42/16 | F3: HO-42-16_05.pdf | H3: ff.317-319 | I3: Unclear - check | K3: Digitised (TNA PDF) | L3: Key quote only | M3: "...we cannot depend or expect much support from our Constables... to request such support for our Persons & property as the nature of the case requires." / Mulgrave: "the object... is to have some military force quartered in the Town at the time of the Election." | N3: 1 Sep 1790 (fwd 6 Sep) | O3: 1790-09-01 | P3: =IF(O3="","",VALUE(LEFT(O3,4))) -> 1790 | Q3: Scarborough | R3: Scarborough | S3: Yorkshire (N. Riding) | T3: Jno Harrison & Jno Woodall, bailiffs; fwd by Henry Phipps (Ld Mulgrave) | U3: Mayor / corporation | V3: Ld Mulgrave, fwd to Grenville | W3: =IF(O3="","",INDEX(Lookups!$B$2:$B$20,MATCH(O3,Lookups!$A$2:$A$20,1))) -> Grenville | X3: Election | Y3: Pre-emptive | Z3: Y | AA3: Military force quartered in town during election | AB3: Unclear | AD3: Forwarded | AI3: Corporation vs freemen threatening to seize control by force at the election; constables unreliable. | Outcome (orig.): Forwarded to Grenville; outcome not in file
A4: HO42-0003 | B4: E03 | C4: Request for troops | D4: N | E4: HO 42/34 | F4: HO-42-34_01.pdf | H4: ff.55-56 | I4: Unclear - check | K4: Digitised (TNA PDF) | L4: Key quote only | M4: "...pull down the mill & destroy the corn & flour therein, situated in the parish of Lamberhurst, belonging to Messrs Webb & Fowle..." | N4: 23 Jan 1795 | O4: 1795-01-23 | P4: =IF(O4="","",VALUE(LEFT(O4,4))) -> 1795 | Q4: Lamberhurst | R4: Lamberhurst | S4: Kent | T4: Charles Jaques, magistrate (for Fowle, mill-owner) | U4: Magistrate / JP | W4: =IF(O4="","",INDEX(Lookups!$B$2:$B$20,MATCH(O4,Lookups!$A$2:$A$20,1))) -> Portland | X4: Food / provisions | Y4: Pre-emptive | Z4: Unclear | AA4: Not specified | AB4: Unclear | AC4: Docket: "Copy of this sent to Ld Amherst Jany 24 with his Grace's opinion that a small number of troops shd be ordered to Lamberhurst to aid the magistrates if necessary." | AD4: Approved | AE4: 24 Jan 1795 | AF4: Whitehall | AG4: Portland -> Amherst | AH4: HO 42 docket | AI4: Flour-mill riot; GRANTED (small number of troops ordered). Clean request+response pair. | Outcome (orig.): Approved
A5: HO42-0004 | B5: E04 | C5: Corps founded | D5: Y | E5: HO 42/34 | F5: HO-42-34_02.pdf | H5: ff.117-118, 122-123 | I5: Unclear - check | K5: Digitised (TNA PDF) | L5: Key quote; full text held | M5: "...expedient to augment the domestic Force of this Country, as well to resist any hostile Attempts... as to suppress any Insurrections... the Object of their arming is, to aid the civil Magistracy." | N5: 28 Jan 1795 (fwd 21 & 26 Feb) | O5: 1795-01-28 | P5: =IF(O5="","",VALUE(LEFT(O5,4))) -> 1795 | Q5: Newcastle upon Tyne | R5: Newcastle upon Tyne | S5: Northumberland | T5: Mayor Francis Johnson; fwd Duke of Northumberland (Ld Lieut) | U5: Mayor / corporation | V5: Duke of Northumberland (Ld Lieut), fwd to HO | W5: =IF(O5="","",INDEX(Lookups!$B$2:$B$20,MATCH(O5,Lookups!$A$2:$A$20,1))) -> Portland | X5: Preventive / general | AC5: His Majesty accepted the offer to form a Volunteer Corps of Infantry for the internal defence of the town; Northumberland protests the loose, self-governing terms. | AD5: Approved | AE5: 26 Feb 1795 | AG5: King via Portland | AH5: Other | AI5: KEY QUOTE. Volunteer infantry corps; full text held. Lord-Lieutenant ambivalence on record. | Outcome (orig.): Approved
A6: HO42-0005 | B6: E05 | C6: Corps armed/expanded | D6: N | E6: HO 42/34 | F6: HO-42-34_03.pdf | H6: ff.186-188 | I6: Unclear - check | K6: Digitised (TNA PDF) | L6: Key quote only | M6: "...I request the favor of Government arming me with forty stand of Small Arms with necessary Accoutrements... & a couple of barrels of ball Cartridges... I cannot but again repeat my former application for a couple of field pieces to be attached to this Company..." | N6: 11 Mar 1795 | O6: 1795-03-11 | P6: =IF(O6="","",VALUE(LEFT(O6,4))) -> 1795 | Q6: Penzance | R6: Penzance | S6: Cornwall | T6: Capt Tremenheere, Penzance Volunteer Company | U6: Volunteer / militia officer | W6: =IF(O6="","",INDEX(Lookups!$B$2:$B$20,MATCH(O6,Lookups!$A$2:$A$20,1))) -> Portland | X6: Other / unclear | AB6: Volunteers only | AI6: Miners' rising dispersed by bayonet/Riot Act; corps deployed with improvised cannon; 20-30 enrolling as 'Penzance Artillery Men'. | CHECK: Disturbance type: 1795 Cornish miners' risings were largely over grain prices - confirm from letters and recode.
A7: HO42-0006 | B7: E05 | C7: Corps armed/expanded | D7: N | E7: HO 42/34 | F7: HO-42-34_03.pdf | H7: ff.199-200 | I7: Unclear - check | K7: Digitised (TNA PDF) | L7: Key quote only | M7: "There being no other Military force at this place but the Volunteer Company, I have thought proper to keep them in constant readiness, which produces an Expence which there is no fund to supply. I therefore request your Grace's directions herein." | N7: 14 Mar 1795 | O7: 1795-03-14 | P7: =IF(O7="","",VALUE(LEFT(O7,4))) -> 1795 | Q7: Penzance | R7: Penzance | S7: Cornwall | T7: Capt Tremenheere | U7: Volunteer / militia officer | W7: =IF(O7="","",INDEX(Lookups!$B$2:$B$20,MATCH(O7,Lookups!$A$2:$A$20,1))) -> Portland | X7: Other / unclear | AB7: Volunteers only | AI7: Funding/authority request tied to keeping the corps mobilised.
A8: HO42-0007 | B8: E05 | C8: Corps armed/expanded | D8: N | E8: HO 42/34 | F8: HO-42-34_03.pdf | H8: f.201 | I8: Unclear - check | K8: Digitised (TNA PDF) | L8: Key quote only | M8: "...humbly beg leave to support the application made to Government by Captain Tremenheere for two field pieces to be attached to his Company." | N8: 14 Mar 1795 | O8: 1795-03-14 | P8: =IF(O8="","",VALUE(LEFT(O8,4))) -> 1795 | Q8: Penzance | R8: Penzance | S8: Cornwall | T8: Mayor & Justices of Penzance (Board, Batten) | U8: Mayor / corporation | W8: =IF(O8="","",INDEX(Lookups!$B$2:$B$20,MATCH(O8,Lookups!$A$2:$A$20,1))) -> Portland | X8: Other / unclear | AB8: Volunteers only | AI8: Corporation endorsement of the arms request.
A9: HO42-0008 | B9: E05 | C9: Request for troops | D9: N | E9: HO 42/34 | F9: HO-42-34_03.pdf | H9: f.210 | I9: Unclear - check | K9: Digitised (TNA PDF) | L9: Key quote only | M9: "...induce us to request Your Lordship to order such regular forces or Militia as may be thought necessary to be sent into this Neighbourhood as speedily as possible in support of the Civil power and in Aid of the Volunteer Companies." PS: "Two companies may with ease be accommodated..." | N9: 16 Mar 1795 | O9: 1795-03-16 | P9: =IF(O9="","",VALUE(LEFT(O9,4))) -> 1795 | Q9: Penzance, Cornwall | R9: Penzance | S9: Cornwall | T9: Wm Borlase, John Price, Thos Pascoe, Richd Hichens (JPs) + Collector of Customs | U9: Magistrate / JP | W9: =IF(O9="","",INDEX(Lookups!$B$2:$B$20,MATCH(O9,Lookups!$A$2:$A$20,1))) -> Portland | X9: Other / unclear | Y9: Actual | Z9: Y | AA9: Regular forces or militia; "two companies may with ease be accommodated" | AB9: Volunteers only | AI9: Formal county-JP request for regulars/militia after Volunteer Companies alone proved insufficient.
A10: HO42-0009 | B10: E06 | C10: Corps armed/expanded | D10: N | E10: HO 42/34 | F10: HO-42-34_01.pdf | H10: ff.9-10 | I10: Unclear - check | K10: Digitised (TNA PDF) | L10: Key quote only | M10: Offer to raise two additional troops (100 men) for his Fencible Regiment; notes Government had declined the expense of purchasing horses. | N10: 4 Jan 1795 | O10: 1795-01-04 | P10: =IF(O10="","",VALUE(LEFT(O10,4))) -> 1795 | Q10: Exeter (Heavitree Barracks) | R10: Exeter | S10: Devon | T10: Montagu Burgoyne | U10: Military officer | W10: =IF(O10="","",INDEX(Lookups!$B$2:$B$20,MATCH(O10,Lookups!$A$2:$A$20,1))) -> Portland | AI10: Officer's offer to expand a fencible corps; fiscal-military bargaining over horse cost.
A11: HO42-0010 | B11: E07 | C11: Corps founded | D11: Y | E11: HO 42/30 | F11: HO-42-30_01.pdf | H11: ff.21-24 | I11: Unclear - check | K11: Digitised (TNA PDF) | L11: Key quote; full text held | M11: "...do without Delay quit the Field of Argument for that of Arms... forming themselves into a Military Association... be formed into Companies of Infantry, but to offer the Service of as many Cavalry as can be mustered... to repel external Violence, suppress internal Commotions..." | N11: 6 May 1794 (res. 24 Mar & 19 Apr) | O11: 1794-05-06 | P11: =IF(O11="","",VALUE(LEFT(O11,4))) -> 1794 | Q11: Birmingham | R11: Birmingham | S11: Warwickshire | T11: John Brooke / J. Morfitt (Loyal True Blues) | U11: Loyalist association | W11: =IF(O11="","",INDEX(Lookups!$B$2:$B$20,MATCH(O11,Lookups!$A$2:$A$20,1))) -> Dundas | X11: Preventive / general | AI11: KEY QUOTE. Loyalist association militarising into infantry+cavalry; ~50-100 enrolled; full text held.
A12: HO42-0011 | B12: E08 | C12: Corps founded | D12: Y | E12: HO 42/30 | F12: HO-42-30_01.pdf | H12: ff.52-53 | I12: Unclear - check | K12: Digitised (TNA PDF) | L12: Key quote only | M12: "...do hereby engage to form ourselves into a military Corps, under the Sanction of Government, to be called the Independent Sheffield Volunteers... in preventing or suppressing all riotous, disorderly & unlawful meetings or assemblies." | N12: 1 May 1794 (fwd 12 May) | O12: 1794-05-01 | P12: =IF(O12="","",VALUE(LEFT(O12,4))) -> 1794 | Q12: Sheffield | R12: Sheffield | S12: Yorkshire (W. Riding) | T12: J. Russell, Dronfield | U12: Loyalist association | W12: =IF(O12="","",INDEX(Lookups!$B$2:$B$20,MATCH(O12,Lookups!$A$2:$A$20,1))) -> Dundas | X12: Preventive / general | AI12: KEY QUOTE. Corps raised in a radical town; 100+ signatures; engagement text held.
A13: HO42-0012 | B13: E09 | C13: Barracks | D13: Y | E13: HO 42/30 | F13: HO-42-30_01.pdf | H13: ff.62-63 | I13: Unclear - check | K13: Digitised (TNA PDF) | L13: Key quote only | M13: "...particularly in case of Riots and Disturbances among the Pitmen and others employed in the Coalworks... the peace... most effectually preserved by the appearance of Cavalry on the Spot ready to assist the civil Power." | N13: 12 May 1794 | O13: 1794-05-12 | P13: =IF(O13="","",VALUE(LEFT(O13,4))) -> 1794 | Q13: Newcastle upon Tyne | R13: Newcastle upon Tyne | S13: Northumberland | T13: Mayor Wm Yielder & corporation | U13: Mayor / corporation | W13: =IF(O13="","",INDEX(Lookups!$B$2:$B$20,MATCH(O13,Lookups!$A$2:$A$20,1))) -> Dundas | X13: Labour / industrial | Y13: Pre-emptive | AA13: Cavalry barracks | AB13: Unclear | AI13: Request to build cavalry barracks, explicitly riot-driven (pitmen).
A14: HO42-0013 | B14: E10 | C14: Barracks | D14: N | E14: HO 42/30 | F14: HO-42-30_01.pdf | H14: ff.16-17 | I14: Unclear - check | K14: Digitised (TNA PDF) | L14: Key quote only | M14: Objection to the siting of proposed barracks at Wells ('a mere Village, free from seditious Societies'). | N14: 5 May 1794 | O14: 1794-05-05 | P14: =IF(O14="","",VALUE(LEFT(O14,4))) -> 1794 | Q14: Wells | R14: Wells | S14: Somerset | T14: Mr Tudway | U14: Private individual | W14: =IF(O14="","",INDEX(Lookups!$B$2:$B$20,MATCH(O14,Lookups!$A$2:$A$20,1))) -> Dundas | X14: Preventive / general | AI14: Marginal - about siting, not raising. Included for completeness. | CHECK: Barracks row is an OBJECTION to siting, not a request - consider separate event type.
A15: HO42-0014 | B15: E11 | C15: Request for troops | D15: N | E15: HO 42/33 | F15: HO-42-33_01.pdf | H15: ~f.43-44 (also narr. ff.220-225 in _03) | I15: Unclear - check | K15: Digitised (TNA PDF) | L15: Key quote only | M15: "...finding the impossibility of quelling a further riot with the civil power only... I am therefore going to send to the Tower for 100 of His Majesty's Guards, and... I shall stand in Need of further military Aid at Night." (also asked Light Horse Volunteers & HAC) | N15: 20-22 Aug 1794 | O15: 1794-08-20 | P15: =IF(O15="","",VALUE(LEFT(O15,4))) -> 1794 | Q15: London | R15: London | S15: Middlesex / City | T15: Lord Mayor (Paul Le Mesurier) | U15: Mayor / corporation | V15: Tower (Guards); HAC; Light Horse Volunteers | W15: =IF(O15="","",INDEX(Lookups!$B$2:$B$20,MATCH(O15,Lookups!$A$2:$A$20,1))) -> Portland | X15: Recruitment / crimping | Y15: Actual | Z15: Y | AA15: 100 Guards from Tower + Light Horse Volunteers & HAC | AB15: Y | AI15: London 'crimp' riots; civil magistrate requesting Guards + volunteer corps. Core request; full transcription pending. | Follow-up in HO 42/33 ff.236-237 (23 Aug 1794): Lord Mayor stands down the Guards but asks the Deputy Governor of the Tower to keep "a strong Picquet of at least Sixty Men ready to come to me on the shortest Notice"; LHV 12-15 men on duty nightly, ~50 Artillery Co.; "if the Rioters should begin again I shall immediately send to the Tower for the Guards". Also ff.240-1 Colquhoun: nearly 500 special constables, LHV & Hackney Association marched to Finsbury Square.
A16: HO42-0015 | B16: E11 | C16: Corps forming (context) | D16: N | E16: HO 42/33 | F16: HO-42-33_03.pdf | H16: ff.160, 162-163 | I16: Unclear - check | K16: Digitised (TNA PDF) | L16: Key quote only | M16: "the Armed Associations which are forming in this quarter of the Metropolis cannot be ready to act for a considerable length of time..." / "none of the Military associations which have been forming in Hackney and the Town Hamlets are yet in a situation to act." | N16: 21 Aug 1794 | O16: 1794-08-21 | P16: =IF(O16="","",VALUE(LEFT(O16,4))) -> 1794 | Q16: London (Hackney, Tower Hamlets) | R16: London | S16: Middlesex | T16: Patrick Colquhoun, Worship Street | U16: Magistrate / JP | W16: =IF(O16="","",INDEX(Lookups!$B$2:$B$20,MATCH(O16,Lookups!$A$2:$A$20,1))) -> Portland | AI16: Evidence of armed associations being raised across metropolitan parishes (context, not a discrete offer).
A17: HO42-0016 | B17: E12 | C17: Corps armed/expanded | D17: N | E17: HO 42/30 | F17: HO-42-30_04.pdf | H17: ff.270-271 | I17: Unclear - check | K17: Digitised (TNA PDF) | L17: Key quote only | M17: "His Majesty having been pleased to approve of the Steps taken in the Isle of Wight to augment by voluntary subscription the internal force of it, and particularly by an increase of the Militia... to apply for two Field Pieces of Cannon to be attached to this Corps. It is proposed that the embodied Company of the Militia shd be trained to the use of the Guns..." | N17: 24 May 1794 | O17: 1794-05-24 | P17: =IF(O17="","",VALUE(LEFT(O17,4))) -> 1794 | Q17: Isle of Wight | R17: Isle of Wight | S17: Hampshire | T17: Thomas Orde (Governor of the Isle of Wight) | U17: Other official | W17: =IF(O17="","",INDEX(Lookups!$B$2:$B$20,MATCH(O17,Lookups!$A$2:$A$20,1))) -> Dundas | X17: Preventive / general | AC17: Militia augmentation already approved by the King; the field-pieces request's outcome not in this file. | AD17: Approved | AH17: Other | AI17: Militia increase by voluntary subscription + request for 2 field pieces; internal-defence framed. Key-quote adjacent (militia augmentation). | Outcome (orig.): (augmentation approved) | CHECK: Key-quote adjacent (militia augmentation).
A18: HO42-0017 | B18: E13 | C18: Request for troops | D18: N | E18: HO 42/33 | F18: HO-42-33_05.pdf | H18: f.377 | I18: Unclear - check | K18: Digitised (TNA PDF) | L18: Key quote only | M18: "This Morning I gave orders for Two hundred extra Constables, & I have also wrote to the Artillery Company & to the Light Horse Volunteers who are and have been in readiness for several hours to co-operate with the Civil Power should occasion require. I have reason to believe the Peace of the City will be preserved." | N18: 22 Nov 1794 | O18: 1794-11-22 | P18: =IF(O18="","",VALUE(LEFT(O18,4))) -> 1794 | Q18: London (Sessions House, Old Bailey) | R18: London | S18: City of London | T18: Lord Mayor of London (Thomas Skinner) | U18: Mayor / corporation | W18: =IF(O18="","",INDEX(Lookups!$B$2:$B$20,MATCH(O18,Lookups!$A$2:$A$20,1))) -> Portland | X18: Radical / political | Y18: Report only | Z18: N | AA18: Artillery Co. & Light Horse Volunteers on standby; 200 extra constables | AB18: Y | AI18: During the Treason Trials (Hardy/Tooke). Civil request to the volunteer corps + 200 extra constables; distinct occasion from the Aug 1794 crimp-riot request. | CHECK: Reclassify? This is a report to HO of local precautions, not a request to government.
A19: HO42-0018 | B19: E14 | C19: Request for troops | D19: N | E19: HO 42/30 | F19: HO-42-30_04.pdf | G19: 30-33 | H19: ff.225, 227 | I19: Folio stamp | K19: Digitised (TNA PDF) | L19: Key quote only | M19: Shuckburgh-Evelyn: "W. Legge of Grosvenor Square called upon me yesterday, expressing much apprehension for himself & neighbours at the unprotected state of the Town of Birmingham by the withdrawing the Cavalry from thence at the present period". Enclosed, Dr Spencer (magistrate): "I hope & trust we shall not be left without one Troop." | N19: 23 May 1794 | O19: 1794-05-23 | P19: =IF(O19="","",VALUE(LEFT(O19,4))) -> 1794 | Q19: Birmingham | R19: Birmingham | S19: Warwickshire | T19: G. Shuckburgh-Evelyn (fwd W. Legge; encl. Dr B. Spencer, magistrate) | U19: MP / peer | V19: Home Office (Nepean?) | W19: =IF(O19="","",INDEX(Lookups!$B$2:$B$20,MATCH(O19,Lookups!$A$2:$A$20,1))) -> Dundas | X19: Radical / political | Y19: Pre-emptive | Z19: Unclear | AA19: Retain at least one troop of cavalry in the town | AB19: Y | AI19: Request to keep cavalry from being withdrawn (regiment under orders for foreign service). Distinct episode from the Loyal True Blues corps (E07). Docket 23 May 1794 "Dom". Addressee inferred - check.
A20: HO42-0019 | B20: E15 | C20: Corps founded | D20: Y | E20: HO 42/30 | F20: HO-42-30_05.pdf | G20: 64-65 | H20: ff.333-334 | I20: Folio stamp | K20: Digitised (TNA PDF) | L20: Key quote only | M20: "...Inclosing to you an account of the late proceedings here, for our internal Defence; not only against our foreign, but, our more to be dreaded, domestic Enemies." | N20: 31 May 1794 | O20: 1794-05-31 | P20: =IF(O20="","",VALUE(LEFT(O20,4))) -> 1794 | Q20: Doncaster | R20: Doncaster | S20: Yorkshire (W. Riding) | T20: Edward Miller | U20: Private individual | V20: Unnamed official (knew his brother & nieces) | W20: =IF(O20="","",INDEX(Lookups!$B$2:$B$20,MATCH(O20,Lookups!$A$2:$A$20,1))) -> Dundas | X20: Radical / political | AI20: KEY QUOTE. Enclosure (account of Doncaster meeting for internal defence) not in this file - check whether a corps or subscription was actually formed; event type provisional. Writer also says his son at Sheffield was "equally alert".
A21: HO42-0020 | B21: E16 | C21: Request for troops | D21: Y | E21: HO 42/33 | F21: HO-42-33_05.pdf | G21: 76-77 | H21: ff.369-370 | I21: Folio stamp | K21: Digitised (TNA PDF) | L21: Key quote only | M21: "Having received this day information that illegal meetings have been held in the town of Kenninghall in this county under a pretence of lowering the price of provisions, and that they have provided to stop waggons and carts loaded with corn, and meal, and have likewise assembled about the bakers shops to seize the bread ... and that they mean to assemble on Monday next at Kenninghall in great numbers - I must request your Grace to order a troop of Horse to be sent immediately to the towns of Harling and Kenninghall to be ready to assist the civil power if necessary." PS: "If the horse are immediately ordered from Norwich they can be at Harling and Kenninghall on Saturday or Sunday." | N21: 4 Dec 1794 | O21: 1794-12-04 | P21: =IF(O21="","",VALUE(LEFT(O21,4))) -> 1794 | Q21: Shadwell Lodge near Thetford (re Kenninghall & Harling) | R21: Kenninghall | S21: Norfolk | T21: Robert John Buxton | U21: MP / peer | V21: Duke of Portland ("My Lord ... your Grace") | W21: =IF(O21="","",INDEX(Lookups!$B$2:$B$21,MATCH(O21,Lookups!$A$2:$A$21,1))) -> Portland | X21: Food / provisions | Y21: Pre-emptive | Z21: Unclear | AA21: One troop of Horse, from Norwich, to Harling and Kenninghall | AB21: N | AI21: Textbook request: food-price assemblies, communication between parishes, troop requested ahead of announced meeting. Writer also calls a general meeting of the principal people of the hundreds at Harling to redress grievances and for "defence of our properties, and the support of the civil power" (possible association - watch for follow-up). Buxton was, I believe, MP for Thetford - verify capacity (MP vs JP). Look for reply in HO 43/6 (Oct 1794-Jul 1795) c. 5-6 Dec 1794.
A22: HO42-0021 | B22: E17 | C22: Request for troops | D22: Y | E22: HO 42/19 | F22: HO-42-19_02.pdf | G22: 31-32, 34 | H22: ff.110-111, 112-113 | I22: Folio stamp | K22: Digitised (TNA PDF) | L22: Key quote only | M22: Under-Sheriff John Brooke, 16 Jul 1791, 7pm: "the attempts which the Magistrates, myself and a numerous party made... proved totally ineffectual. Several Men have lost their lives... nor is there the least gleam of hope that good order can be restored without the aid of a considerable Military Force. Many more Houses are devoted & can only be saved by an early arrival of Troops." Dundas reply to magistrates J. Carles & R. Spencer, 16 Jul (f.112): "I had this morning the honor of receiving your letter of yesterday's date, giving an account of the Riot... I have dispatched a Messenger to Nottingham with directions to the Officer commanding the 15th Dragoons... to send three Troops of that Regiment instantly to Birmingham, to assist the Civil Magistrate". | N22: 15-16 Jul 1791 | O22: 1791-07-15 | P22: =IF(O22="","",VALUE(LEFT(O22,4))) -> 1791 | Q22: Birmingham | R22: Birmingham | S22: Warwickshire | T22: Magistrates J. Carles & R. Spencer (letter of 15 Jul, original not seen); John Brooke, Under-Sheriff of Warwickshire (16 Jul) | U22: Magistrate / JP | V22: Henry Dundas, Home Secretary | W22: =IF(O22="","",INDEX(Lookups!$B$2:$B$22,MATCH(O22,Lookups!$A$2:$A$22,1))) -> Dundas | X22: Radical / political | Y22: Actual | Z22: Y | AA22: "a considerable Military Force" | AB22: N | AC22: Dundas, 16 Jul: 3 troops of 15th Dragoons from Nottingham sent "instantly"; 17 Jul: 3 troops 11th Dragoons from Uxbridge also ordered (f.119), all available force to be collected (f.115 to Lt-Col Churchill). | AD22: Approved | AE22: 1791-07-16 | AF22: Whitehall | AG22: Henry Dundas | AH22: Other | AI22: Priestley ("Church and King") riots, 14-17 Jul 1791. Magistrates' original request of 15 Jul is referred to but not located in 19_01/19_02 - CHECK 19_03. Response source: Home Office draft/copy filed in HO 42. Troop orders 16-23 Jul tabulated at HO 42/19_01 f.70. Also Sam. Garbett to Hawkesbury 16-17 Jul (ff.109, 126): magistrates left town, "the horrible Scene of Plunder continues & no doubt will continue untill Troops arrive."
A23: HO42-0022 | B23: E17 | C23: Request for troops | D23: N | E23: HO 42/19 | F23: HO-42-19_02.pdf | G23: 60 | H23: f.136 | I23: Folio stamp | K23: Digitised (TNA PDF) | L23: Key quote only | M23: "Since sealing the inclosed we think necessary earnestly to intreat a further aid without delay fearing the three Troops may suffer if they come... and we are obliged to require their immediate entrance tho' yet hope they may not be wanted. 20 minutes past 2 o'Clock Sunday Afternoon." | N23: Sunday [17 Jul 1791] | O23: 1791-07-17 | P23: =IF(O23="","",VALUE(LEFT(O23,4))) -> 1791 | Q23: Birmingham | R23: Birmingham | S23: Warwickshire | T23: Birmingham magistrates (unsigned postscript) | U23: Magistrate / JP | V23: Home Office (inferred) | W23: =IF(O23="","",INDEX(Lookups!$B$2:$B$23,MATCH(O23,Lookups!$A$2:$A$23,1))) -> Dundas | X23: Radical / political | Y23: Actual | Z23: Y | AA23: Further aid beyond the three troops | AB23: N | AI23: Follow-up request in same episode. CHECK: writers and addressee inferred (enclosure separated).
A24: HO42-0023 | B24: E18 | C24: Request for troops | D24: N | E24: HO 42/19 | F24: HO-42-19_02.pdf | G24: 53, 80-81, 83-84, 86 | H24: ff.131, 154-155, 157-158, 165 | I24: Folio stamp | K24: Digitised (TNA PDF) | L24: Key quote only | M24: Coventry, 17 Jul 1791 (Town Clerk for Mayor & Justices): "without the aid of military exertions, it is not likely to abate... with little encouragement, numbers may soon be found in Coventry, to engage in similar Outrages". Forwarded by Eardley & John Wilmot (MPs), Bedford Row 18 Jul: Mayor & Justices "desire we will without Delay, apply to you for a Regiment to be quartered there, in order to discourage & suppress all Disposition to disturb the Peace of the City." | N24: 17-18 Jul 1791 | O24: 1791-07-17 | P24: =IF(O24="","",VALUE(LEFT(O24,4))) -> 1791 | Q24: Coventry | R24: Coventry | S24: Warwickshire | T24: Mayor & Justices of Coventry (via Town Clerk); fwd by Eardley & John Wilmot | U24: Mayor / corporation | V24: Henry Dundas (via the city's MPs) | W24: =IF(O24="","",INDEX(Lookups!$B$2:$B$24,MATCH(O24,Lookups!$A$2:$A$24,1))) -> Dundas | X24: Radical / political | Y24: Pre-emptive | Z24: Unclear | AA24: A regiment quartered in the city | AB24: N | AC24: Nepean to Wilmot, 18 Jul (f.155): troops on their march towards Birmingham "will stop at Coventry to assist the Civil Magistrates in quelling any Disturbances that may arise." | AD24: Approved | AE24: 1791-07-18 | AF24: Whitehall | AG24: Evan Nepean | AH24: Other | AI24: Spillover fear from Priestley riots. Route: forwarded by MPs. Writer role of Wilmot/Eardley as MPs - CHECK. | Coventry Town Clerk Edw. Inge, 22 Jul (HO 42/19_03 f.244): Mayor & magistrates thank Govt "for the polite and speedy attention to their request. The appearance of the Military has had the desired effect".
A25: HO42-0024 | B25: E19 | C25: Request for troops | D25: N | E25: HO 42/19 | F25: HO-42-19_03.pdf | G25: 17-18 | H25: ff.178-179 | I25: Folio stamp | K25: Digitised (TNA PDF) | L25: Key quote only | M25: "I am desired by several of the principal Inhabitants, to inform you, a disposition has appeared among the People to riot. By the interposition of the Peace Officers no ill consequences have as yet happened... it may be for the consideration of Government, how far it may be prudent to send a small force. We hear more Troops are coming to Birmingham probably if necessary, One Troop may be spared from thence." | N25: 19 Jul 1791 | O25: 1791-07-19 | P25: =IF(O25="","",VALUE(LEFT(O25,4))) -> 1791 | Q25: Wolverhampton | R25: Wolverhampton | S25: Staffordshire | T25: Wm Beto Taylor | U25: Private individual | V25: Home Office (inferred) | W25: =IF(O25="","",INDEX(Lookups!$B$2:$B$25,MATCH(O25,Lookups!$A$2:$A$25,1))) -> Dundas | X25: Radical / political | Y25: Pre-emptive | Z25: N | AA25: A small force; one troop from Birmingham | AB25: N | AI25: Priestley-riot spillover. CHECK: writer's role (signs for 'principal Inhabitants'; may be a magistrate). Later (19_03 ff.222-226): troop of dragoons stationed at Wolverhampton; Taylor reports magistrates satisfied.
A26: HO42-0025 | B26: E20 | C26: Request for troops | D26: N | E26: HO 42/19 | F26: HO-42-19_03.pdf | G26: 43-44, 82-83 | H26: ff.203-204, 238-239 | I26: Folio stamp | K26: Digitised (TNA PDF) | L26: Key quote only | M26: Mayor John Harris, 21 Jul 1791: transmits anonymous threatening letter; magistrates "feel it their duty after what has happened at Birmingham to transmit the information to Government, submitting to its wisdom the expediency of stationing a competent number of Troops within a day's march of so large a City as Bristol; that in case of any disturbance it may be speedily quelled." Enclosed letter (18 Jul): "Near two 2000 Good Harty hail Strong Ruffins Which will Pull down your fine Manchin houses... Shall Share the Same fate as them at Burmingham". | N26: 21-22 Jul 1791 | O26: 1791-07-21 | P26: =IF(O26="","",VALUE(LEFT(O26,4))) -> 1791 | Q26: Bristol | R26: Bristol | S26: Gloucestershire / Bristol | T26: John Harris, Mayor of Bristol (with Aldermen) | U26: Mayor / corporation | V26: Henry Dundas | W26: =IF(O26="","",INDEX(Lookups!$B$2:$B$26,MATCH(O26,Lookups!$A$2:$A$26,1))) -> Dundas | X26: Radical / political | Y26: Pre-emptive | Z26: N | AA26: A competent number of troops within a day's march | AB26: N | AC26: Govt (Dundas absent) ordered 3rd Regt of Infantry from Reading to Marlborough and Devizes, to proceed to Bristol if the Mayor thinks necessary (Harris to [Home Office], 25 Jul, HO 42/19_04 f.268). Magistrates chose to rely on constables "as no actual tumult has yet taken place". | AD26: Approved | AE26: 1791-07-23 | AH26: Other | AI26: Follow-up 22 Jul (f.238): second anonymous letter, all quiet. Bristol was a county corporate.
A27: HO42-0026 | B27: E21 | C27: Request for troops | D27: N | E27: HO 42/19 | F27: HO-42-19_03.pdf | G27: 90 | H27: f.246 | I27: Folio stamp | K27: Digitised (TNA PDF) | L27: Key quote only | M27: "A Handbill stuck up this morning, on the Churches and several other public Places... together with the murmurs of most of the Manufacturers and Common People here, have given occasion for much alarm... We therefore, the only Magistrates resident in the Borough, take the liberty of requesting that you will give orders for three Troops of some Horse Regiment to march immediately to this Place, and be assisting us in the quelling any Riots which may arise in Leicester. If it should be inconvenient... we request you will have the goodness to order as many as you can". | N27: 23 Jul 1791 | O27: 1791-07-23 | P27: =IF(O27="","",VALUE(LEFT(O27,4))) -> 1791 | Q27: Leicester | R27: Leicester | S27: Leicestershire | T27: Jno Darnes (Mayor), Henry Watchorn, W. Clark - magistrates | U27: Mayor / corporation | V27: Secretary at War (copy sent to Home Office) | W27: =IF(O27="","",INDEX(Lookups!$B$2:$B$27,MATCH(O27,Lookups!$A$2:$A$27,1))) -> Dundas | X27: Radical / political | Y27: Pre-emptive | Z27: Unclear | AA27: Three troops of horse | AB27: N | AI27: ROUTE: request addressed to the Secretary at War, not the Home Secretary; copy filed in HO 42. Docket 22 Jul (letter dated 23 Jul - CHECK). Mayor's name read as 'Darnes' - CHECK.
A28: HO42-0027 | B28: E22 | C28: Request for troops | D28: Y | E28: HO 42/19 | F28: HO-42-19_04.pdf | G28: 9-10, 16, 48-54 | H28: ff.256-257, 262, 294-300 | I28: Folio stamp | K28: Digitised (TNA PDF) | L28: Key quote only | M28: "considerable Bodies of disorderly people in this Neighbourhood have lately several times assembled... with the Riotous Intention of preventing the Commissioners acting under the Authority of an Inclosure Bill... burnt the farming property and broke the Windows of several Houses... openly avowed their Intentions of laying open the Inclosures... it is earnestly requested that you Sir will have the Goodness of affording immediate Military Assistance to suppress the first attempts to rioting... and to prevent their Connection with the Rioters from Birmingham". | N28: 23 Jul 1791 | O28: 1791-07-23 | P28: =IF(O28="","",VALUE(LEFT(O28,4))) -> 1791 | Q28: Sheffield | R28: Sheffield | S28: Yorkshire (W. Riding) | T28: Jas Wilkinson JP; Thos Eyre, Collector for the Town; Joseph Ward, Master Cutler | U28: Magistrate / JP | V28: Henry Dundas | W28: =IF(O28="","",INDEX(Lookups!$B$2:$B$28,MATCH(O28,Lookups!$A$2:$A$28,1))) -> Dundas | X28: Enclosure | Y28: Actual | Z28: Unclear | AA28: "speedy and effective Military Assistance" | AB28: N | AC28: Whitehall 25 Jul (f.262, Dundas absent): two troops of 4th Dragoons from York and two troops [light horse] from Nottingham ordered to Sheffield. Troops arrived 27-28 Jul; riot that night (gaol broken, Wilkinson's house at Broom Hall attacked, hay ricks burnt) dispersed by the military (ff.294-300). | AD28: Approved | AE28: 1791-07-25 | AF28: Whitehall | AG28: Home Office (Dundas absent) | AH28: Other | AI28: ANTI-ENCLOSURE riots + fear of Birmingham spillover (disturbance type: enclosure - consider adding 'Enclosure' to vocabulary). Signers met privately to avoid a public meeting that 'might excite public suspicions'. Request route: direct. Rioters attacked the requesting magistrate's house after troops arrived.
A29: HO42-0028 | B29: E22 | C29: Request for troops | D29: Y | E29: HO 42/19 | F29: HO-42-19_05.pdf | G29: 47 | H29: f.354 | I29: Folio stamp | K29: Digitised (TNA PDF) | L29: Key quote only | M29: "every thing has remain'd in a state of perfect Tranquillity, but this can only be attributed to the Appearance of the Military... for the Number of treasonable Inscriptions on Walls and Doors and frequent nocturnal Exclamations in the Streets such as 'No King' 'No Corn Bill' 'No Taxes' &c and the incendiary Letters... give just Grounds of fear that, if the Military were remov'd before all the Causes which gave Rise to the Commotions had subsided the worst of Consequences would in all probability immediately ensue & therefore I must beg Leave once more to express the Wish of the Town in general that they may be permitted to remain here". | N29: 31 Jul 1791 | O29: 1791-07-31 | P29: =IF(O29="","",VALUE(LEFT(O29,4))) -> 1791 | Q29: Sheffield | R29: Sheffield | S29: Yorkshire (W. Riding) | T29: Thos Eyre, Town Collector | U29: Other official | V29: Henry Dundas | W29: =IF(O29="","",INDEX(Lookups!$B$2:$B$29,MATCH(O29,Lookups!$A$2:$A$29,1))) -> Dundas | X29: Radical / political | Y29: Pre-emptive | Z29: N | AA29: Retain troops already sent | AB29: Y | AI29: REQUEST TO KEEP TROOPS (same question as Birmingham May 1794 - pending JV's answer). Same episode as HO42-0027. Also 1 Aug (ff.367-368): West Riding magistrates at Sheffield ask Govt to fund prosecutions of rioters; riot began by breaking the debtors' prison, neighbourhood riots 'in avowed & actual Opposition to an Act... for an Inclosure of waste Ground'.
A30: HO42-0029 | B30: E23 | C30: Corps founded | D30: Y | E30: HO 42/19 | F30: HO-42-19_08.pdf | G30: 48-50 | H30: ff.570-572 | I30: Folio stamp | K30: Digitised (TNA PDF) | L30: Key quote only | M30: Covering letter: gentlemen have signed "the Inclosed Association calculated for their mutual Protection against any sudden Rising of the Lower Class of People". Resolution (f.571): "We who subscribe our Names, reflecting upon the late violent insurrections arising from no publick provocation or principle whatever, but from a desire of Equality and Plunder... engage upon the first appearance or symptoms of such Evils to assemble not only all the Chief Constables and Petty constables but also our several Tenants and Servants, to Arm them and to resort to the Parts where the Evil exists... We conceive that if the Lord Lieutenant should judge proper to obtain a discretional power from Government to call for Military Aid without loss of time... such timely exertions would be more than superior to the Mob in its first stage". | N30: 6 Sept 1791 | O30: 1791-09-06 | P30: =IF(O30="","",VALUE(LEFT(O30,4))) -> 1791 | Q30: Snitterfield | R30: Snitterfield | S30: Warwickshire | T30: Unidentified correspondent for subscribing gentlemen (list of subscribers f.572) | U30: Loyalist association | V30: Home Office (inferred) | W30: =IF(O30="","",INDEX(Lookups!$B$2:$B$30,MATCH(O30,Lookups!$A$2:$A$30,1))) -> Dundas | X30: Preventive / general | AI30: Armed association of landowners, tenants and servants after the Priestley riots; also asks that the Lord Lieutenant get discretionary power to call military aid. CHECK: writer's name and place reading ('Snitterfield').
A31: HO42-0030 | B31: E24 | C31: Corps founded | D31: N | E31: HO 42/19 | F31: HO-42-19_08.pdf | G31: 52-53 | H31: ff.574-575 | I31: Folio stamp | K31: Digitised (TNA PDF) | L31: Key quote only | M31: "Lord Orford... has transmitted to you, an Association I had suggested to my Neighbours & afterwards to many of the principal Gentlemen of Landed property in this part of the County, at a period when the explosions of political Enthusiasm or Craft might break forth here or elsewhere, as at Birmingham. In this County in particular Vigilance was necessary, as upon any sudden decline of the Norwich Manufactures or upon a rise of provisions, Riots have followed & our Magistrates in this part of the County have sometimes been intimidated to inaction, or a disgraceful compromise." | N31: 7 Sept 1791 | O31: 1791-09-07 | P31: =IF(O31="","",VALUE(LEFT(O31,4))) -> 1791 | Q31: Rainham | R31: Raynham | S31: Norfolk | T31: [Lord] Townshend | U31: MP / peer | V31: Henry Dundas (via Lord Orford) | W31: =IF(O31="","",INDEX(Lookups!$B$2:$B$31,MATCH(O31,Lookups!$A$2:$A$31,1))) -> Dundas | X31: Preventive / general | AC31: Dundas to Earl of Orford, Whitehall Sept 1791 (HO 42/19_09 ff.632-634): motives deserve "the highest commendation, but I cannot help expressing some doubts whether the measure of putting People of the description mentioned by your Lordship in arms may not on general principles be liable to some objections... dangerous precedents generally originate in commendable motives". On discretionary power to call military aid: "the Military stationed in the County are ordered to obey at all times the Civil Magistrates in case of emergency". | AD31: Denied | AE31: 1791-09 | AF31: Whitehall | AG31: Henry Dundas | AH31: Other | AI31: Landowners' association in west Norfolk; association text itself (sent via Lord Orford) not seen here. Note magistrates 'intimidated to inaction, or a disgraceful compromise' in food riots. CHECK signer (Townshend). | Outcome coded Denied = arming discouraged (not formally refused); discretionary military power declined as unnecessary.
A32: HO42-0031 | B32: E25 | C32: Request for troops | D32: N | E32: HO 42/20 | F32: HO-42-20_3.pdf | G32: 33 | H32: f.177 | I32: Folio stamp | K32: Digitised (TNA PDF) | L32: Key quote only | M32: "the Journeymen Carpenters of this Town (who are a very powerful body of Men) had a meeting... & were heard to say, that if the abolition of the Slave Trade takes place, some Houses in the Town (which they had mark'd) shou'd be pull'd down... tho' I do not (I confess) apprehend much danger myself (having the 30th Regt of Foot here) yet... I shou'd recommend three Troops of Horse to be quarter'd in the neighbourhood till the ferment subsides a little viz.t One at Wigan, another at Warrington". | N32: 14 Apr 1792 | O32: 1792-04-14 | P32: =IF(O32="","",VALUE(LEFT(O32,4))) -> 1792 | Q32: Liverpool | R32: Liverpool | S32: Lancashire | T32: Henry Blundell, Mayor of Liverpool | U32: Mayor / corporation | V32: Henry Dundas | W32: =IF(O32="","",INDEX(Lookups!$B$2:$B$32,MATCH(O32,Lookups!$A$2:$A$32,1))) -> Dundas | X32: Labour / industrial | Y32: Pre-emptive | Z32: N | AA32: Three troops of horse (Wigan, Warrington, ...) | AB32: Y | AI32: Threat tied to slave-trade abolition (carpenters/shipwrights dependent on the trade). Second page not read - CHECK third location.
A33: HO42-0032 | B33: E26 | C33: Request for troops | D33: N | E33: HO 42/20 | F33: HO-42-20_3.pdf | G33: 35-38 | H33: ff.179-182 | I33: Folio stamp | K33: Digitised (TNA PDF) | L33: Key quote only | M33: "the great body of Carpenters intended to leave their work on Monday Morning unless their Wages were advanced... perhaps you will be so good, Sir, as to order One of the Troops of Grays, which are now at Manchester into Warrington or at least send Orders to the Commanding Officer in Manchester to march a Troop or two, if Circumstances shou'd compel me to call for them... There seems too general an appearance of discontent amongst all Artificers & Labourers". Encloses flatmen's notice (coal flats) demanding 1s per ton per trip. | N33: 27 May 1792 | O33: 1792-05-27 | P33: =IF(O33="","",VALUE(LEFT(O33,4))) -> 1792 | Q33: Liverpool | R33: Liverpool | S33: Lancashire | T33: Henry Blundell, Mayor of Liverpool | U33: Mayor / corporation | V33: Henry Dundas | W33: =IF(O33="","",INDEX(Lookups!$B$2:$B$33,MATCH(O33,Lookups!$A$2:$A$33,1))) -> Dundas | X33: Labour / industrial | Y33: Contingent | Z33: N | AA33: One troop of Greys to Warrington, or standing orders to march 1-2 troops on call | AB33: Y | AC33: Dundas 30 May (acknowledged 5 Jun, f.181: 'very much obliged by your attention to my request'). 5 Jun: no disturbance, merchants conceded part of carpenters' demand. "I should have been able to have suppressed any Riot, but I judg'd it prudent to be guarded against the worst & my reason for requesting Horse was, I think for dispersing a Mob, One Troop of Horse is better than half a Regt of Foot for avoiding blood shed". | AD33: Approved | AE33: 1792-05-30 | AH33: Other | AI33: Wage strike (carpenters, coal flatmen). Key rationale: cavalry preferred to infantry to avoid bloodshed. Mayor also urges Govt to build Anglican churches in new manufacturing villages (Methodists 'inimical to our happy Constitution').
A34: HO42-0033 | B34: E27 | C34: Request for troops | D34: N | E34: HO 42/20 | F34: HO-42-20_3.pdf | G34: 39-40 | H34: ff.183-184 | I34: Folio stamp | K34: Digitised (TNA PDF) | L34: Key quote only | M34: "the appearance of Assistance from the Military has had the very best Effect, the Mob are dispers'd & the people began to return yester' Morning to their Work... We are under very particular obligations to Major Ramsay of the Grays for the immediate Assistance he afforded us; he only rec'd our Express on Wednesday Morning at 5 o'Clock & he had two Troops in Wigan before One... This Riot by being taken in time (& which wou'd certainly have spread very far) has in my Opinion sav'd many from the Gallows". | N34: 7 Oct 1792 | O34: 1792-10-03 | P34: =IF(O34="","",VALUE(LEFT(O34,4))) -> 1792 | Q34: Wigan collieries (letter from Liverpool) | R34: Wigan | S34: Lancashire | T34: Henry Blundell, Mayor of Liverpool (as coal proprietor) | U34: Mayor / corporation | V34: Henry Dundas | W34: =IF(O34="","",INDEX(Lookups!$B$2:$B$34,MATCH(O34,Lookups!$A$2:$A$34,1))) -> Dundas | X34: Labour / industrial | Y34: Actual | Z34: Unclear | AA34: Express to Major Ramsay (Greys) - two troops; infantry under Capt Hall | AB34: Y | AC34: Two troops of Greys at Wigan within 8 hours of express; HO letter of 3 Oct acknowledged. | AD34: Approved | AE34: 1792-10-03 | AH34: Other | AI34: ROUTE: express sent DIRECTLY to the military commander (Major Ramsay), HO informed - 'local request, reported' route. Colliers' riot, engines stopped 2 days. Date (ISO) is approx. date of request (Wednesday before 7 Oct = 3 Oct) - CHECK. Cavalry released, infantry kept at Wigan.
A35: HO42-0034 | B35: E28 | C35: Request for troops | D35: N | E35: HO 42/20 | F35: HO-42-20_4.pdf | G35: 16-17 | H35: ff.243-244 | I35: Folio stamp | K35: Digitised (TNA PDF) | L35: Key quote only | M35: "a Disorder in the Town having happened the night before... occasioned by a Disagreement between some of the military and the populace... a more serious Affray took place between the military and the Inhabitants than any that had before happened... We have therefore requested the Commanding Officer of the Regiment at Nottingham... to make the Exchange but as there may be some Danger that whilst any of the same Regiment remain here that the Disputes... may not be forgotten We therefore submit it to you with great Deference whether it might not contribute to the Quiet of this place to send here immediately a part of some other Corps." | N35: 10-11 May 1792 | O35: 1792-05-10 | P35: =IF(O35="","",VALUE(LEFT(O35,4))) -> 1792 | Q35: Sheffield | R35: Sheffield | S35: Yorkshire (W. Riding) | T35: Saml Tooker, Fr. Edmunds, B. Frank (West Riding JPs) | U35: Magistrate / JP | V35: Henry Dundas (inferred) | W35: =IF(O35="","",INDEX(Lookups!$B$2:$B$35,MATCH(O35,Lookups!$A$2:$A$35,1))) -> Dundas | X35: Other / unclear | Y35: Actual | Z35: N | AA35: Replace quartered troops with part of another corps | AB35: Y | AI35: Riot between soldiers and townspeople (troops stationed since July 1791 enclosure riots). Request to SWAP troops, not add - borderline. Also asked CO at Nottingham directly (local route).
A36: HO42-0035 | B36: E29 | C36: Request for troops | D36: N | E36: HO 42/20 | F36: HO-42-20_4.pdf | G36: 64 | H36: f.289 | I36: Folio stamp | K36: Digitised (TNA PDF) | L36: Key quote only | M36: "We are honor'd with your favor of 23d. signifying approbation of our Calling in the Military from Kidderminster and Bromsgrove, and are happy to inform you the Town is at present in a State of perfect tranquility... the next week being Holiday presume it may be prudent to continue the present Troops." | N36: 25 May 1792 | O36: 1792-05-25 | P36: =IF(O36="","",VALUE(LEFT(O36,4))) -> 1792 | Q36: Birmingham | R36: Birmingham | S36: Warwickshire | T36: J. Carles & R. Spencer (magistrates) | U36: Magistrate / JP | V36: Henry Dundas | W36: =IF(O36="","",INDEX(Lookups!$B$2:$B$36,MATCH(O36,Lookups!$A$2:$A$36,1))) -> Dundas | X36: Other / unclear | Y36: Report only | Z36: Unclear | AA36: Troops from Kidderminster & Bromsgrove (already called); keep them over holiday week | AB36: Y | AC36: HO letter of 23 May approved their calling in the military. | AD36: Approved | AE36: 1792-05-23 | AH36: Other | AI36: ROUTE: local request to nearby garrisons, then reported; plus request to KEEP troops. Cause of May 1792 Birmingham disturbance not stated here - CHECK neighbouring folios.
A37: HO42-0036 | B37: E30 | C37: Request for troops | D37: Y | E37: HO 42/20 | F37: HO-42-20_4.pdf | G37: 76-77 | H37: ff.301-302 | I37: Folio stamp | K37: Digitised (TNA PDF) | L37: Key quote only | M37: "The Magistrates of this Borough being under some apprehensions of a Riot, a request was made to the Secretary at War in the Month of August last, that the Commanding Officer at York might have directions to Order a sufficient number of Troops to march to Leeds immediately upon a requisition... signed by the Mayor or Recorder and two Aldermen... we therefore request that such directions may be given... it is not our intention to call for Military aid till we think it safe no longer to be without it". | N37: 26 May 1792 | O37: 1792-05-26 | P37: =IF(O37="","",VALUE(LEFT(O37,4))) -> 1792 | Q37: Leeds | R37: Leeds | S37: Yorkshire (W. Riding) | T37: Wade Browne, Mayor | U37: Mayor / corporation | V37: Henry Dundas | W37: =IF(O37="","",INDEX(Lookups!$B$2:$B$37,MATCH(O37,Lookups!$A$2:$A$37,1))) -> Dundas | X37: Preventive / general | Y37: Contingent | Z37: N | AA37: Standing orders to CO at York to march sufficient troops on the Mayor's requisition | AB37: N | AI37: Earlier request Aug 1791 to Secretary at War (granted: 4th Dragoons at Pontefract) - a second, unlogged request; orders leaked and were 'publickly talked of at Leeds'. Asks CO not to divulge instructions. Follows the royal proclamation of 21 May 1792 against seditious writings.
A38: HO42-0037 | B38: E31 | C38: Request for troops | D38: N | E38: HO 42/20 | F38: HO-42-20_5.pdf | G38: 44, 48, 60, 62-67 | H38: ff.352, 357, 369, 371-376 | I38: Folio stamp | K38: Digitised (TNA PDF) | L38: Key quote only | M38: 6 Jun: "there are considerable Numbers of People in the Streets which make it advisable to continue the Military for a short Time, after which they propose to dismiss a part of them and to keep a small Number to patrole the Streets till tomorrow Morning, as was done on Tuesday Night". 8 Jun: "It was thought necessary from the Appearance & Behaviour of the People about 8 o'Clock to order a small party of the Horse Guards to patrole the Street for some time but they are now dismissed". | N38: 6-10 Jun 1792 | O38: 1792-06-05 | P38: =IF(O38="","",VALUE(LEFT(O38,4))) -> 1792 | Q38: Mount Street & South Audley Street, Westminster | R38: London (Mayfair) | S38: Middlesex | T38: Magistrates acting in Mount Street (Baker, Keene, Bond) | U38: Magistrate / JP | V38: Evan Nepean (Under-Secretary) | W38: =IF(O38="","",INDEX(Lookups!$B$2:$B$38,MATCH(O38,Lookups!$A$2:$A$38,1))) -> Dundas | X38: Other / unclear | Y38: Report only | Z38: Unclear | AA38: Military / small party of Horse Guards to patrol | AB38: Y | AI38: ROUTE: troops called locally by magistrates, reported to HO by half-hourly notes. Cause of Mount Street riots not stated in these notes - CHECK. St George's Hanover Square vestry thanks Horse Guards officers and Maj-Gen Buckley 11 Jun (ff.371-376). 10 Jun: crowd dispersed 'without the Appearance of any Soldier or even of any Constable'.
A39: HO42-0038 | B39: E32 | C39: Barracks | D39: N | E39: HO 42/20 | F39: HO-42-20_7.pdf | G39: 53 | H39: f.528 | I39: Folio stamp | K39: Digitised (TNA PDF) | L39: Key quote only | M39: "Not being able to get a place in the Town or even in the Vicinity of Sheffield for the temporary accommodation of the Troops, He has entered into engagements for building Barracks at the distance of about three quarters of a Mile from the Town, on the Halifax Road - The distance will prevent too free an intercourse between the Soldiery and Inhabitants, without occasioning any inconvenience in obtaining supplies from the market... The buildings will be so constructed that they may at any time, if necessary, be enlarged." | N39: 19 Jul 1792 | O39: 1792-07-19 | P39: =IF(O39="","",VALUE(LEFT(O39,4))) -> 1792 | Q39: Sheffield | R39: Sheffield | S39: Yorkshire (W. Riding) | T39: Col. Oliver De Lancey (Barrack-Master), to the Secretary at War; abstract read by the King | U39: Military officer | V39: Secretary at War (abstract filed in HO 42) | W39: =IF(O39="","",INDEX(Lookups!$B$2:$B$39,MATCH(O39,Lookups!$A$2:$A$39,1))) -> Dundas | X39: Preventive / general | AA39: Barracks for 3 troops of dragoons | AI39: Part of the 1792 barrack-building programme for manufacturing towns (cover: 'Plans &c of Barracks to be built at Sheffield, Manchester & Nottingham under agreements made by Col. de Lancey', July 1792, 'Read by The King'). Cost estimate (f.515): Sheffield 3 troops £2000; Manchester 6 troops £7900; Nottingham 3 troops £3800; Birmingham 3 troops £5000. KEY: siting chosen to limit contact between soldiers and inhabitants - links to May 1792 soldier-townspeople riot (HO42-0034). Land from Vincent Eyre.
A40: HO42-0039 | B40: E33 | C40: Barracks | D40: N | E40: HO 42/20 | F40: HO-42-20_7.pdf | G40: 61 | H40: f.532 | I40: Folio stamp | K40: Digitised (TNA PDF) | L40: Key quote only | M40: "The speculations of the Inhabitants have greatly increased the price of Land in and about Manchester - He has obtained Six acres at three half pence per Yard, amounting to an Annual rent of £187.14 from Mr Egerton half a mile to the Southward of the Town. The extent is absolutely necessary for the purposes of discipline." | N40: 7 Aug 1792 | O40: 1792-08-07 | P40: =IF(O40="","",VALUE(LEFT(O40,4))) -> 1792 | Q40: Manchester | R40: Manchester | S40: Lancashire | T40: Col. Oliver De Lancey (Barrack-Master), to the Secretary at War; abstract read by the King | U40: Military officer | V40: Secretary at War (abstract filed in HO 42) | W40: =IF(O40="","",INDEX(Lookups!$B$2:$B$40,MATCH(O40,Lookups!$A$2:$A$40,1))) -> Dundas | X40: Preventive / general | AA40: Barracks for 6 troops of dragoons | AI40: Part of the 1792 barrack-building programme for manufacturing towns (cover: 'Plans &c of Barracks to be built at Sheffield, Manchester & Nottingham under agreements made by Col. de Lancey', July 1792, 'Read by The King'). Cost estimate (f.515): Sheffield 3 troops £2000; Manchester 6 troops £7900; Nottingham 3 troops £3800; Birmingham 3 troops £5000. Builder Chas. McNevin. Context in same file: May 1792 'spirit of combination' among 2nd Dragoons at Manchester over provision prices (ff.520-523).
...

Sheet Leads
A1: Lead ID | B1: Event type | C1: Place | D1: County | E1: Date (ISO) | F1: Summary | G1: Archive ref (as cited) | H1: Cited by | I1: Verified in original? | J1: Priority | K1: Notes / conflicts
A2: L001 | B2: Request for troops | C2: Oxford | D2: Oxfordshire | E2: 1800-09-04 | F2: Troops (11th Light Dragoons) sent to Oxford; town clerk protests on behalf of volunteers; HO reply reassures them. | G2: HO 42/51 ff.36-7, 59-60; HO 50/388; HO 43/12 pp.106-7 (King to Taunton, 8 Sep 1800) | H2: Bend 2018; Gee (via other session) | I2: N | J2: High | K2: CONFLICT: Gee says Vice-Chancellor requested troops; Bend says Portland sent them unrequested on Rev. D. Hughes's letter, V-C later asked they stay. Other session dated the reply 1801 - wrong, it is 1800.
A3: L002 | B3: Request for troops | C3: Banbury | D3: Oxfordshire | E3: 1800 | F3: Mayor wants "soldiers unconnected with the place" because yeomanry sympathised with rioters. | G3: HO 42/51 f.116 | H3: Gee (via other session) | I3: N | J3: High | K3: Local force distrusted - fits "civil power inadequate".
A4: L003 | B4: Request for troops | C4: Birmingham | D4: Warwickshire | E4: 1800-11 | F4: Troops sent on Lord Lieutenants' information without consulting magistrates, who objected. | G4: HO 43/12 pp.313-6; HO 42/53 ff.404-5 | H4: Bend 2018 | I4: N | J4: Medium | K4: Deployment WITHOUT request - code as unrequested, not as request.
A5: L004 | B5: Other | C5: Berkeley | D5: Gloucestershire | E5: 1800-09-16 | F5: Earl of Berkeley: restraint in sending for soldiers "till... absolutely necessary"; cross-county correspondence rumoured. | G5: HO 42/51 ff.168-9 | H5: Bend 2018 | I5: N | J5: Low | K5: Evidence of reluctance to request.
A6: L005 | B6: Corps armed/expanded | C6: Henley | D6: Oxfordshire | E6: 1800 | F6: Anonymous threat leads to armed-association patrols. | G6: HO 42/49 f.393 | H6: Gee (via other session) | I6: N | J6: Medium
A7: L006 | B7: Corps armed/expanded | C7: Hambledon & Wickham | D7: Hampshire | E7: 1800-03 | F7: Volunteers kept in constant readiness against grain-price disorder; Lt-Col Palmer seeks pay for nightly patrols; WO objects only to pay. | G7: HO 50/48 ff.153, 165, 209, 246 | H7: Gee (via other session) | I7: N | J7: Medium | K7: Money for internal-order duty.
A8: L007 | B8: Request for troops | C8: Stony / Fenny Stratford | D8: Buckinghamshire | E8: 1796-03-25 | F8: Newport & Buckingham Yeomanry in riot context. | G8: HO 50/330 (Nugent [Buckingham], 25 Mar 1796) | H8: Gee (via other session) | I8: N | J8: High | K8: Check whether this is a request or a report.
A9: L008 | B9: Request for troops | C9: Tavistock | D9: Devon | E9: 1801-03-14 | F9: Riot-related correspondence. | G9: HO 50/49 (Bray to Dundas, 14 Mar 1801) | H9: Gee (via other session) | I9: N | J9: High
A10: L009 | B10: Other | C10: Sheffield | D10: Yorkshire (W. Riding) | E10: c.1800-01 | F10: Reliability enquiries on the corps; HO advises not to call it on active duty. | G10: HO 50/49 | H10: Gee (via other session) | I10: N | J10: Medium | K10: A government response on corps reliability.
A11: L010 | B11: Corps founded | C11: Kettering & Rothwell | D11: Northamptonshire | E11: 1798-05-25 | F11: Associations recommended to the Lord Lieutenant "entirely in terms of their usefulness against disturbances" after 1795 Kettering food riot. | G11: HO 50/42 (James Curry to Earl of Northampton) | H11: Gee (via other session) | I11: N | J11: Medium | K11: Key-quote candidate.
A12: L011 | B12: Corps founded | C12: Hampshire (county) | D12: Hampshire | E12: 1794-06-11 | F12: Plan for a county-wide "Association for assisting the Civil Power" to suppress seditious tumults at magistrates' call. | G12: Hampshire RO 65 M 85/1 | H12: Gee (via other session) | I12: N | J12: Medium | K12: Key-quote candidate. County record office, not TNA.
A13: L012 | B13: Corps armed/expanded | C13: Windsor | D13: Berkshire | E13: 1803-08 | F13: Magistrates, after repeated riots, request leave to levy an additional troop of fencible cavalry. | G13: Berkshire RO D/ERa O8/2 (5) | H13: Gee (via other session) | I13: N | J13: Low | K13: 1803 - outside 1790s window; confirm period with JV.
A14: L013 | B14: Corps armed/expanded | C14: Hampton Lucy | D14: Warwickshire | E14: 1807-10-07 | F14: Volunteers' unauthorised paid permanent duty allowed though "irregular". | G14: HO 51/86 (Hawkesbury to Warwick) | H14: Gee (via other session) | I14: N | J14: Low | K14: 1807 - outside window.
A15: L014 | B15: Other | C15: National | D15: - | E15: 1797-04 | F15: Draft circular: volunteer/yeomanry COs to help magistrates apprehend persons in treasonable proceedings (June 1797 proclamation). | G15: HO 50/55 | H15: Gee (via other session) | I15: N | J15: Medium | K15: Policy context.
